# JavaScript 异步编程

## 事件循环

JavaScript 代码在浏览器环境中，是以一种非阻塞，单线程的方式执行的，这表示在同一时刻只有一个代码段在执行。为了协调事件、用户交互、脚本、UI 渲染和网络处理等行为，JavaScript 采用 EventLoop（事件循环）来防止主线程的不阻塞。

JavaScript 代码的执行过程中，除了依靠函数调用栈来搞定函数的执行顺序外，还依靠任务队列（task queue）来搞定另外一些代码的执行。整个执行过程，我们称为事件循环过程。一个线程中，事件循环是唯一的，但是任务队列可以拥有多个。任务队列又分为宏任务（macro-task）与微任务（micro-task）。

常见的宏任务有：

\- script(整体代码)

\- setTimeout

\- setInterval

常见的微任务有：

\- Promise.then()

\- MutationObserver

\- queueMicrotask

\- process.nextTick（node.js）

当 JavaScript 代码第一次执行的时候，JavaScript 引擎会解析这段代码，并将其中的同步代码按照执行顺序加入执行栈中，然后从头开始执行。如果当前执行的是一个方法，那么js会向执行栈中添加这个方法的执行环境，然后进入这个执行环境继续执行其中的代码。当这个执行环境中的代码，执行完毕并返回结果后，JavaScript 会退出这个执行环境并把这个执行环境销毁，回到上一个方法的执行环境。这个过程反复进行，直到执行栈中的代码全部执行完毕。

当遇到异步事件时，JavaScript 引擎并不会一直等待其返回结果，而是会将这个事件挂起，继续执行执行栈中的其他任务。当一个异步事件返回结果后，JavaScript 会将这个事件加入与当前执行栈不同的另一个队列，我们称之为任务队列。

根据这个异步事件的类型，这个事件会被加入到对应的宏任务队列或者微任务队列中去。并且在当前执行栈为空的时候，主线程会查看微任务队列是否有事件存在。如果不存在，那么再去宏任务队列中取出一个事件并把对应的回到加入当前执行栈；如果存在，则会依次执行队列中事件对应的回调，直到微任务队列为空，然后去宏任务队列中取出最前面的一个事件，把对应的回调加入当前执行栈。如此反复，进入循环。

## Promise

### 概述

- Promise 存在三种状态：pending（等待）,fulfilled（成功）,rejected（失败）。
- pending 为初始状态，只能转化为 fulfilled 和 rejected，一旦状态发生改变，便不能再被更改为其他状态。
- Promise 接受一个函数为参数，该函数存在两个参数：resolve，reject。resolve 可将 Promise 从 pending 转化为 fulfilled，reject  可将 Promise 从 pending 转化为 rejected。

### 基本用法

返回resolve

```js
const promise = new Promise((resolve, reject) => {
  resolve(100)
})

promise.then((value) => {
  console.log('resolved', value)
},(error) => {
  console.log('rejected', error)
})
```

返回reject

```js
const promise = new Promise((resolve, reject) => {
  reject(new Error('promise rejected'))
})

promise.then((value) => {
  console.log('resolved', value)
},(error) => {
  console.log('rejected', error)
})
```

### 链式调用

```js
const p = new Promise((resolve) => {
  resolve('111')
})

p.then((value) => {
  console.log(value) // 111
  return '222'
})
  .then((value) => {
    console.log(value) // 222
    return new Promise((resolve) => {
      console.log('333')
      resolve('444')
    })
  })
  .then((value) => {
    console.log(value) // 444
  })

// 111 -> 222 -> 333 -> 444
```



- promise对象then方法，返回了全新的promise对象。可以再继续调用then方法，如果return的不是promise对象，而是一个值，那么这个值会作为resolve的值传递，如果没有值，默认是undefined
- 后面的then方法就是在为上一个then返回的Promise注册回调
- 前面then方法中回调函数的返回值会作为后面then方法回调的参数
- 如果回调中返回的是Promise，那后面then方法的回调会等待它的结束

> .then() 里面的实参应该为函数，如果不是函数，就无视它。
>
> 例：
>
> Promise.resolve(1).then(2).then(Promise.resolve(3)).then(console.log) 
>
> =>
>
> Promise.resolve(1).then( val => val ).then( val => val ).then( console.log )

### 异常处理

#### 1. then 中回调的onRejected方法

```js
const p = new Promise((resolve, reject) => {
  reject('rejected')
})
p.then(
  (val) => {},
  (err) => {
    console.log(err) // rejected
  }
)
```

#### 2. .catch()(推荐)

```js
const p = new Promise((resolve, reject) => {
  reject('rejected')
})
p.catch((error) => {
  console.log(error) // rejected
})

// 等效于以下写法

const p = new Promise((resolve, reject) => {
  reject('rejected')
})
p.then(undefined, (err) => {
  console.log(err) //rejected
})
```

.catch形式和前面then里面的第二个参数的形式，两者异常捕获的区别：

- .catch()是对上一个.then()返回的promise进行处理，不过第一个promise的报错也顺延到了catch中，而then的第二个参数形式，只能捕获第一个promise的报错，如果当前then的resolve函数处理中有报错是捕获不到的。

所以.catch是给整个promise链条注册的一个失败回调。

#### 3. 全局对象上的unhandledrejection事件（不推荐）

还可以在全局对象上注册一个**unhandledrejection**事件，处理那些代码中没有被手动捕获的promise异常，当然**并不推荐使用**。

更合理的是：在代码中明确捕获每一个可能的异常，而不是丢给全局处理。

```js
// 浏览器
window.addEventListener('unhandledrejection', event => {
  const { reason, promise } = event
  console.log(reason, promise)

  //reason => Promise 失败原因，一般是一个错误对象
  //promise => 出现异常的Promise对象

  event.preventDefault()
}, false)

// node
process.on('unhandledRejection', (reason, promise) => {
  console.log(reason, promise)

  //reason => Promise 失败原因，一般是一个错误对象
  //promise => 出现异常的Promise对象
})
```

### 静态方法

Promise.resolve

返回一个带着给定值解析过的`Promise`对象，如果参数本身就是一个`Promise`对象，则直接返回这个`Promise`对象。

Promise.reject

`Promise.reject()`方法返回一个带有拒绝原因的`Promise`对象。

> 参考
>
> https://developer.mozilla.org/zh-CN/docs/Web/JavaScript/Reference/Global_Objects/Promise

### Generator 异步方案（ES2015）

```js
function * foo () {
  const.log('start')
  try {
    const res = yield 'foo'
    console.log(res)
  } catch (e) {
    console.log(e )
  }
}

const generator = foo()
const result = generator.next()
console.log(result)

generator.throw(new Error('Generator error'))
```

> 参考
>
> https://juejin.cn/post/6844903556718264328#heading-0

###  Async Await

> 参考
>
> https://juejin.cn/post/6844903621360943118

